[2024-02-10 17:28:48,463] {taskinstance.py:1159} INFO - Dependencies all met for <TaskInstance: test_dag_dependencies.write_date scheduled__2024-02-10T17:27:00+00:00 [queued]>
[2024-02-10 17:28:48,520] {taskinstance.py:1159} INFO - Dependencies all met for <TaskInstance: test_dag_dependencies.write_date scheduled__2024-02-10T17:27:00+00:00 [queued]>
[2024-02-10 17:28:48,523] {taskinstance.py:1356} INFO - 
--------------------------------------------------------------------------------
[2024-02-10 17:28:48,526] {taskinstance.py:1357} INFO - Starting attempt 1 of 2
[2024-02-10 17:28:48,537] {taskinstance.py:1358} INFO - 
--------------------------------------------------------------------------------
[2024-02-10 17:28:48,609] {taskinstance.py:1377} INFO - Executing <Task(BashOperator): write_date> on 2024-02-10 17:27:00+00:00
[2024-02-10 17:28:48,645] {standard_task_runner.py:79} INFO - Running: ['***', 'tasks', 'run', 'test_dag_dependencies', 'write_date', 'scheduled__2024-02-10T17:27:00+00:00', '--job-id', '328', '--raw', '--subdir', 'DAGS_FOLDER/dag_test_dependencies.py', '--cfg-path', '/tmp/tmpotujpbhw', '--error-file', '/tmp/tmphb9muwr1']
[2024-02-10 17:28:48,647] {standard_task_runner.py:80} INFO - Job 328: Subtask write_date
[2024-02-10 17:28:48,633] {standard_task_runner.py:52} INFO - Started process 1227 to run task
[2024-02-10 17:28:48,843] {task_command.py:369} INFO - Running <TaskInstance: test_dag_dependencies.write_date scheduled__2024-02-10T17:27:00+00:00 [running]> on host f4c5b03650dc
[2024-02-10 17:28:49,220] {taskinstance.py:1571} INFO - Exporting the following env vars:
AIRFLOW_CTX_DAG_EMAIL=fidiasierides@gmail.com
AIRFLOW_CTX_DAG_OWNER=Fidias
AIRFLOW_CTX_DAG_ID=test_dag_dependencies
AIRFLOW_CTX_TASK_ID=write_date
AIRFLOW_CTX_EXECUTION_DATE=2024-02-10T17:27:00+00:00
AIRFLOW_CTX_TRY_NUMBER=1
AIRFLOW_CTX_DAG_RUN_ID=scheduled__2024-02-10T17:27:00+00:00
[2024-02-10 17:28:49,225] {subprocess.py:62} INFO - Tmp dir root location: 
 /tmp
[2024-02-10 17:28:49,227] {subprocess.py:74} INFO - Running command: ['bash', '-c', 'pwd && cd .. && cd .. && pwd && cd ~/Users/fidiasieridis/Documents/GitHub/weather-data-store && date >> date.txt']
[2024-02-10 17:28:49,259] {subprocess.py:85} INFO - Output:
[2024-02-10 17:28:49,271] {subprocess.py:92} INFO - /tmp/***tmp3uck6bhp
[2024-02-10 17:28:49,277] {subprocess.py:92} INFO - /
[2024-02-10 17:28:49,281] {subprocess.py:92} INFO - bash: line 1: cd: /home/***/Users/fidiasieridis/Documents/GitHub/weather-data-store: No such file or directory
[2024-02-10 17:28:49,286] {subprocess.py:96} INFO - Command exited with return code 1
[2024-02-10 17:28:49,316] {taskinstance.py:1889} ERROR - Task failed with exception
Traceback (most recent call last):
  File "/home/airflow/.local/lib/python3.7/site-packages/airflow/operators/bash.py", line 195, in execute
    f'Bash command failed. The command returned a non-zero exit code {result.exit_code}.'
airflow.exceptions.AirflowException: Bash command failed. The command returned a non-zero exit code 1.
[2024-02-10 17:28:49,324] {taskinstance.py:1400} INFO - Marking task as UP_FOR_RETRY. dag_id=test_dag_dependencies, task_id=write_date, execution_date=20240210T172700, start_date=20240210T172848, end_date=20240210T172849
[2024-02-10 17:28:49,387] {standard_task_runner.py:97} ERROR - Failed to execute job 328 for task write_date (Bash command failed. The command returned a non-zero exit code 1.; 1227)
[2024-02-10 17:28:49,423] {local_task_job.py:156} INFO - Task exited with return code 1
[2024-02-10 17:28:49,560] {local_task_job.py:273} INFO - 0 downstream tasks scheduled from follow-on schedule check
