[2024-02-10 18:46:00,992] {taskinstance.py:1159} INFO - Dependencies all met for <TaskInstance: test_dag_dependencies.write_date scheduled__2024-02-10T18:45:00+00:00 [queued]>
[2024-02-10 18:46:00,999] {taskinstance.py:1159} INFO - Dependencies all met for <TaskInstance: test_dag_dependencies.write_date scheduled__2024-02-10T18:45:00+00:00 [queued]>
[2024-02-10 18:46:00,999] {taskinstance.py:1356} INFO - 
--------------------------------------------------------------------------------
[2024-02-10 18:46:00,999] {taskinstance.py:1357} INFO - Starting attempt 1 of 2
[2024-02-10 18:46:00,999] {taskinstance.py:1358} INFO - 
--------------------------------------------------------------------------------
[2024-02-10 18:46:01,011] {taskinstance.py:1377} INFO - Executing <Task(BashOperator): write_date> on 2024-02-10 18:45:00+00:00
[2024-02-10 18:46:01,013] {standard_task_runner.py:52} INFO - Started process 4104 to run task
[2024-02-10 18:46:01,016] {standard_task_runner.py:79} INFO - Running: ['***', 'tasks', 'run', 'test_dag_dependencies', 'write_date', 'scheduled__2024-02-10T18:45:00+00:00', '--job-id', '441', '--raw', '--subdir', 'DAGS_FOLDER/dag_test_dependencies.py', '--cfg-path', '/tmp/tmpbae3wnqc', '--error-file', '/tmp/tmp6relx63z']
[2024-02-10 18:46:01,016] {standard_task_runner.py:80} INFO - Job 441: Subtask write_date
[2024-02-10 18:46:01,046] {task_command.py:369} INFO - Running <TaskInstance: test_dag_dependencies.write_date scheduled__2024-02-10T18:45:00+00:00 [running]> on host f4c5b03650dc
[2024-02-10 18:46:01,088] {taskinstance.py:1571} INFO - Exporting the following env vars:
AIRFLOW_CTX_DAG_EMAIL=fidiasierides@gmail.com
AIRFLOW_CTX_DAG_OWNER=Fidias
AIRFLOW_CTX_DAG_ID=test_dag_dependencies
AIRFLOW_CTX_TASK_ID=write_date
AIRFLOW_CTX_EXECUTION_DATE=2024-02-10T18:45:00+00:00
AIRFLOW_CTX_TRY_NUMBER=1
AIRFLOW_CTX_DAG_RUN_ID=scheduled__2024-02-10T18:45:00+00:00
[2024-02-10 18:46:01,089] {subprocess.py:62} INFO - Tmp dir root location: 
 /tmp
[2024-02-10 18:46:01,090] {subprocess.py:74} INFO - Running command: ['bash', '-c', 'cd ~/Users/fidiasieridis/Desktop/Weather_Airflow && date >> date.txt']
[2024-02-10 18:46:01,095] {subprocess.py:85} INFO - Output:
[2024-02-10 18:46:01,096] {subprocess.py:92} INFO - bash: line 1: cd: /home/***/Users/fidiasieridis/Desktop/Weather_Airflow: No such file or directory
[2024-02-10 18:46:01,096] {subprocess.py:96} INFO - Command exited with return code 1
[2024-02-10 18:46:01,104] {taskinstance.py:1889} ERROR - Task failed with exception
Traceback (most recent call last):
  File "/home/airflow/.local/lib/python3.7/site-packages/airflow/operators/bash.py", line 195, in execute
    f'Bash command failed. The command returned a non-zero exit code {result.exit_code}.'
airflow.exceptions.AirflowException: Bash command failed. The command returned a non-zero exit code 1.
[2024-02-10 18:46:01,107] {taskinstance.py:1400} INFO - Marking task as UP_FOR_RETRY. dag_id=test_dag_dependencies, task_id=write_date, execution_date=20240210T184500, start_date=20240210T184600, end_date=20240210T184601
[2024-02-10 18:46:01,114] {standard_task_runner.py:97} ERROR - Failed to execute job 441 for task write_date (Bash command failed. The command returned a non-zero exit code 1.; 4104)
[2024-02-10 18:46:01,156] {local_task_job.py:156} INFO - Task exited with return code 1
[2024-02-10 18:46:01,178] {local_task_job.py:273} INFO - 0 downstream tasks scheduled from follow-on schedule check
