[2024-02-10 16:32:09,470] {taskinstance.py:1159} INFO - Dependencies all met for <TaskInstance: test_dag_dependencies.write_date scheduled__2024-02-10T15:35:00+00:00 [queued]>
[2024-02-10 16:32:09,502] {taskinstance.py:1159} INFO - Dependencies all met for <TaskInstance: test_dag_dependencies.write_date scheduled__2024-02-10T15:35:00+00:00 [queued]>
[2024-02-10 16:32:09,506] {taskinstance.py:1356} INFO - 
--------------------------------------------------------------------------------
[2024-02-10 16:32:09,507] {taskinstance.py:1357} INFO - Starting attempt 2 of 2
[2024-02-10 16:32:09,507] {taskinstance.py:1358} INFO - 
--------------------------------------------------------------------------------
[2024-02-10 16:32:09,553] {taskinstance.py:1377} INFO - Executing <Task(BashOperator): write_date> on 2024-02-10 15:35:00+00:00
[2024-02-10 16:32:09,572] {standard_task_runner.py:79} INFO - Running: ['***', 'tasks', 'run', 'test_dag_dependencies', 'write_date', 'scheduled__2024-02-10T15:35:00+00:00', '--job-id', '314', '--raw', '--subdir', 'DAGS_FOLDER/dag_test_dependencies.py', '--cfg-path', '/tmp/tmpq_ddo1vs', '--error-file', '/tmp/tmpr7_u35gs']
[2024-02-10 16:32:09,578] {standard_task_runner.py:80} INFO - Job 314: Subtask write_date
[2024-02-10 16:32:09,564] {standard_task_runner.py:52} INFO - Started process 1115 to run task
[2024-02-10 16:32:09,740] {task_command.py:369} INFO - Running <TaskInstance: test_dag_dependencies.write_date scheduled__2024-02-10T15:35:00+00:00 [running]> on host f4c5b03650dc
[2024-02-10 16:32:09,896] {taskinstance.py:1571} INFO - Exporting the following env vars:
AIRFLOW_CTX_DAG_EMAIL=fidiasierides@gmail.com
AIRFLOW_CTX_DAG_OWNER=Fidias
AIRFLOW_CTX_DAG_ID=test_dag_dependencies
AIRFLOW_CTX_TASK_ID=write_date
AIRFLOW_CTX_EXECUTION_DATE=2024-02-10T15:35:00+00:00
AIRFLOW_CTX_TRY_NUMBER=2
AIRFLOW_CTX_DAG_RUN_ID=scheduled__2024-02-10T15:35:00+00:00
[2024-02-10 16:32:09,904] {subprocess.py:62} INFO - Tmp dir root location: 
 /tmp
[2024-02-10 16:32:09,907] {subprocess.py:74} INFO - Running command: ['bash', '-c', 'pwd && cd .. && cd .. && pwd && cd ~/Users/fidiasieridis/Documents/GitHub/weather-data-store && date >> date.txt']
[2024-02-10 16:32:09,923] {subprocess.py:85} INFO - Output:
[2024-02-10 16:32:09,929] {subprocess.py:92} INFO - /tmp/***tmpntlivi70
[2024-02-10 16:32:09,963] {subprocess.py:92} INFO - /
[2024-02-10 16:32:09,971] {subprocess.py:92} INFO - bash: line 1: cd: /home/***/Users/fidiasieridis/Documents/GitHub/weather-data-store: No such file or directory
[2024-02-10 16:32:09,972] {subprocess.py:96} INFO - Command exited with return code 1
[2024-02-10 16:32:10,005] {taskinstance.py:1889} ERROR - Task failed with exception
Traceback (most recent call last):
  File "/home/airflow/.local/lib/python3.7/site-packages/airflow/operators/bash.py", line 195, in execute
    f'Bash command failed. The command returned a non-zero exit code {result.exit_code}.'
airflow.exceptions.AirflowException: Bash command failed. The command returned a non-zero exit code 1.
[2024-02-10 16:32:10,017] {taskinstance.py:1400} INFO - Marking task as FAILED. dag_id=test_dag_dependencies, task_id=write_date, execution_date=20240210T153500, start_date=20240210T163209, end_date=20240210T163210
[2024-02-10 16:32:10,084] {standard_task_runner.py:97} ERROR - Failed to execute job 314 for task write_date (Bash command failed. The command returned a non-zero exit code 1.; 1115)
[2024-02-10 16:32:10,114] {local_task_job.py:156} INFO - Task exited with return code 1
[2024-02-10 16:32:10,267] {local_task_job.py:273} INFO - 0 downstream tasks scheduled from follow-on schedule check
