[2024-02-11 12:26:02,919] {taskinstance.py:1159} INFO - Dependencies all met for <TaskInstance: test_dag.write_date_file scheduled__2024-02-11T12:20:00+00:00 [queued]>
[2024-02-11 12:26:02,928] {taskinstance.py:1159} INFO - Dependencies all met for <TaskInstance: test_dag.write_date_file scheduled__2024-02-11T12:20:00+00:00 [queued]>
[2024-02-11 12:26:02,928] {taskinstance.py:1356} INFO - 
--------------------------------------------------------------------------------
[2024-02-11 12:26:02,928] {taskinstance.py:1357} INFO - Starting attempt 2 of 2
[2024-02-11 12:26:02,928] {taskinstance.py:1358} INFO - 
--------------------------------------------------------------------------------
[2024-02-11 12:26:02,992] {taskinstance.py:1377} INFO - Executing <Task(BashOperator): write_date_file> on 2024-02-11 12:20:00+00:00
[2024-02-11 12:26:03,009] {standard_task_runner.py:52} INFO - Started process 175 to run task
[2024-02-11 12:26:03,029] {standard_task_runner.py:79} INFO - Running: ['***', 'tasks', 'run', 'test_dag', 'write_date_file', 'scheduled__2024-02-11T12:20:00+00:00', '--job-id', '805', '--raw', '--subdir', 'DAGS_FOLDER/dag_test_simple.py', '--cfg-path', '/tmp/tmpmiwuai9s', '--error-file', '/tmp/tmp0d3pztp2']
[2024-02-11 12:26:03,030] {standard_task_runner.py:80} INFO - Job 805: Subtask write_date_file
[2024-02-11 12:26:03,243] {task_command.py:369} INFO - Running <TaskInstance: test_dag.write_date_file scheduled__2024-02-11T12:20:00+00:00 [running]> on host 354d8ce2bde7
[2024-02-11 12:26:03,423] {taskinstance.py:1571} INFO - Exporting the following env vars:
AIRFLOW_CTX_DAG_EMAIL=fidiasierides@gmail.com
AIRFLOW_CTX_DAG_OWNER=Fidias
AIRFLOW_CTX_DAG_ID=test_dag
AIRFLOW_CTX_TASK_ID=write_date_file
AIRFLOW_CTX_EXECUTION_DATE=2024-02-11T12:20:00+00:00
AIRFLOW_CTX_TRY_NUMBER=2
AIRFLOW_CTX_DAG_RUN_ID=scheduled__2024-02-11T12:20:00+00:00
[2024-02-11 12:26:03,430] {subprocess.py:62} INFO - Tmp dir root location: 
 /tmp
[2024-02-11 12:26:03,432] {subprocess.py:74} INFO - Running command: ['bash', '-c', 'cd ~/Users/fidiasieridis/Documents/GitHub/weather-data-store && date >> ai_core.txt']
[2024-02-11 12:26:03,473] {subprocess.py:85} INFO - Output:
[2024-02-11 12:26:03,483] {subprocess.py:92} INFO - bash: line 1: cd: /home/***/Users/fidiasieridis/Documents/GitHub/weather-data-store: No such file or directory
[2024-02-11 12:26:03,484] {subprocess.py:96} INFO - Command exited with return code 1
[2024-02-11 12:26:03,545] {taskinstance.py:1889} ERROR - Task failed with exception
Traceback (most recent call last):
  File "/home/airflow/.local/lib/python3.7/site-packages/airflow/operators/bash.py", line 195, in execute
    f'Bash command failed. The command returned a non-zero exit code {result.exit_code}.'
airflow.exceptions.AirflowException: Bash command failed. The command returned a non-zero exit code 1.
[2024-02-11 12:26:03,550] {taskinstance.py:1400} INFO - Marking task as FAILED. dag_id=test_dag, task_id=write_date_file, execution_date=20240211T122000, start_date=20240211T122602, end_date=20240211T122603
[2024-02-11 12:26:03,563] {standard_task_runner.py:97} ERROR - Failed to execute job 805 for task write_date_file (Bash command failed. The command returned a non-zero exit code 1.; 175)
[2024-02-11 12:26:03,587] {local_task_job.py:156} INFO - Task exited with return code 1
[2024-02-11 12:26:03,641] {local_task_job.py:273} INFO - 0 downstream tasks scheduled from follow-on schedule check
