[2024-02-11 12:22:00,815] {taskinstance.py:1159} INFO - Dependencies all met for <TaskInstance: test_dag.write_date_file scheduled__2024-02-11T12:21:00+00:00 [queued]>
[2024-02-11 12:22:00,823] {taskinstance.py:1159} INFO - Dependencies all met for <TaskInstance: test_dag.write_date_file scheduled__2024-02-11T12:21:00+00:00 [queued]>
[2024-02-11 12:22:00,823] {taskinstance.py:1356} INFO - 
--------------------------------------------------------------------------------
[2024-02-11 12:22:00,823] {taskinstance.py:1357} INFO - Starting attempt 1 of 2
[2024-02-11 12:22:00,823] {taskinstance.py:1358} INFO - 
--------------------------------------------------------------------------------
[2024-02-11 12:22:00,836] {taskinstance.py:1377} INFO - Executing <Task(BashOperator): write_date_file> on 2024-02-11 12:21:00+00:00
[2024-02-11 12:22:00,842] {standard_task_runner.py:52} INFO - Started process 370 to run task
[2024-02-11 12:22:00,844] {standard_task_runner.py:79} INFO - Running: ['***', 'tasks', 'run', 'test_dag', 'write_date_file', 'scheduled__2024-02-11T12:21:00+00:00', '--job-id', '784', '--raw', '--subdir', 'DAGS_FOLDER/dag_test_simple.py', '--cfg-path', '/tmp/tmpw2au6rw5', '--error-file', '/tmp/tmp2yjz62jz']
[2024-02-11 12:22:00,845] {standard_task_runner.py:80} INFO - Job 784: Subtask write_date_file
[2024-02-11 12:22:00,879] {task_command.py:369} INFO - Running <TaskInstance: test_dag.write_date_file scheduled__2024-02-11T12:21:00+00:00 [running]> on host f4c5b03650dc
[2024-02-11 12:22:01,522] {taskinstance.py:1571} INFO - Exporting the following env vars:
AIRFLOW_CTX_DAG_EMAIL=fidiasierides@gmail.com
AIRFLOW_CTX_DAG_OWNER=Fidias
AIRFLOW_CTX_DAG_ID=test_dag
AIRFLOW_CTX_TASK_ID=write_date_file
AIRFLOW_CTX_EXECUTION_DATE=2024-02-11T12:21:00+00:00
AIRFLOW_CTX_TRY_NUMBER=1
AIRFLOW_CTX_DAG_RUN_ID=scheduled__2024-02-11T12:21:00+00:00
[2024-02-11 12:22:01,577] {subprocess.py:62} INFO - Tmp dir root location: 
 /tmp
[2024-02-11 12:22:01,587] {subprocess.py:74} INFO - Running command: ['bash', '-c', 'cd ~/Users/fidiasieridis/Documents/GitHub/weather-data-store && date >> ai_core.txt']
[2024-02-11 12:22:01,740] {subprocess.py:85} INFO - Output:
[2024-02-11 12:22:01,771] {subprocess.py:92} INFO - bash: line 1: cd: /home/***/Users/fidiasieridis/Documents/GitHub/weather-data-store: No such file or directory
[2024-02-11 12:22:01,820] {subprocess.py:96} INFO - Command exited with return code 1
[2024-02-11 12:22:02,252] {taskinstance.py:1889} ERROR - Task failed with exception
Traceback (most recent call last):
  File "/home/airflow/.local/lib/python3.7/site-packages/airflow/operators/bash.py", line 195, in execute
    f'Bash command failed. The command returned a non-zero exit code {result.exit_code}.'
airflow.exceptions.AirflowException: Bash command failed. The command returned a non-zero exit code 1.
[2024-02-11 12:22:02,285] {taskinstance.py:1400} INFO - Marking task as UP_FOR_RETRY. dag_id=test_dag, task_id=write_date_file, execution_date=20240211T122100, start_date=20240211T122200, end_date=20240211T122202
[2024-02-11 12:22:02,382] {standard_task_runner.py:97} ERROR - Failed to execute job 784 for task write_date_file (Bash command failed. The command returned a non-zero exit code 1.; 370)
[2024-02-11 12:22:02,421] {local_task_job.py:156} INFO - Task exited with return code 1
[2024-02-11 12:22:02,560] {local_task_job.py:273} INFO - 0 downstream tasks scheduled from follow-on schedule check
