[2024-02-11 12:16:34,932] {taskinstance.py:1159} INFO - Dependencies all met for <TaskInstance: test_dag.write_date_file scheduled__2024-02-11T08:03:00+00:00 [queued]>
[2024-02-11 12:16:34,973] {taskinstance.py:1159} INFO - Dependencies all met for <TaskInstance: test_dag.write_date_file scheduled__2024-02-11T08:03:00+00:00 [queued]>
[2024-02-11 12:16:34,981] {taskinstance.py:1356} INFO - 
--------------------------------------------------------------------------------
[2024-02-11 12:16:34,990] {taskinstance.py:1357} INFO - Starting attempt 2 of 2
[2024-02-11 12:16:34,995] {taskinstance.py:1358} INFO - 
--------------------------------------------------------------------------------
[2024-02-11 12:16:35,090] {taskinstance.py:1377} INFO - Executing <Task(BashOperator): write_date_file> on 2024-02-11 08:03:00+00:00
[2024-02-11 12:16:35,152] {standard_task_runner.py:52} INFO - Started process 87 to run task
[2024-02-11 12:16:35,238] {standard_task_runner.py:79} INFO - Running: ['***', 'tasks', 'run', 'test_dag', 'write_date_file', 'scheduled__2024-02-11T08:03:00+00:00', '--job-id', '773', '--raw', '--subdir', 'DAGS_FOLDER/dag_test_simple.py', '--cfg-path', '/tmp/tmpf5itumpd', '--error-file', '/tmp/tmp0euefyy0']
[2024-02-11 12:16:35,240] {standard_task_runner.py:80} INFO - Job 773: Subtask write_date_file
[2024-02-11 12:16:35,957] {task_command.py:369} INFO - Running <TaskInstance: test_dag.write_date_file scheduled__2024-02-11T08:03:00+00:00 [running]> on host f4c5b03650dc
[2024-02-11 12:16:36,284] {taskinstance.py:1571} INFO - Exporting the following env vars:
AIRFLOW_CTX_DAG_EMAIL=fidiasierides@gmail.com
AIRFLOW_CTX_DAG_OWNER=Fidias
AIRFLOW_CTX_DAG_ID=test_dag
AIRFLOW_CTX_TASK_ID=write_date_file
AIRFLOW_CTX_EXECUTION_DATE=2024-02-11T08:03:00+00:00
AIRFLOW_CTX_TRY_NUMBER=2
AIRFLOW_CTX_DAG_RUN_ID=scheduled__2024-02-11T08:03:00+00:00
[2024-02-11 12:16:36,286] {subprocess.py:62} INFO - Tmp dir root location: 
 /tmp
[2024-02-11 12:16:36,306] {subprocess.py:74} INFO - Running command: ['bash', '-c', 'cd ~/Users/fidiasieridis/Documents/GitHub/weather-data-store && date >> ai_core.txt']
[2024-02-11 12:16:36,316] {subprocess.py:85} INFO - Output:
[2024-02-11 12:16:36,333] {subprocess.py:92} INFO - bash: line 1: cd: /home/***/Users/fidiasieridis/Documents/GitHub/weather-data-store: No such file or directory
[2024-02-11 12:16:36,338] {subprocess.py:96} INFO - Command exited with return code 1
[2024-02-11 12:16:36,377] {taskinstance.py:1889} ERROR - Task failed with exception
Traceback (most recent call last):
  File "/home/airflow/.local/lib/python3.7/site-packages/airflow/operators/bash.py", line 195, in execute
    f'Bash command failed. The command returned a non-zero exit code {result.exit_code}.'
airflow.exceptions.AirflowException: Bash command failed. The command returned a non-zero exit code 1.
[2024-02-11 12:16:36,391] {taskinstance.py:1400} INFO - Marking task as FAILED. dag_id=test_dag, task_id=write_date_file, execution_date=20240211T080300, start_date=20240211T121634, end_date=20240211T121636
[2024-02-11 12:16:36,440] {standard_task_runner.py:97} ERROR - Failed to execute job 773 for task write_date_file (Bash command failed. The command returned a non-zero exit code 1.; 87)
[2024-02-11 12:16:36,488] {local_task_job.py:156} INFO - Task exited with return code 1
[2024-02-11 12:16:36,658] {local_task_job.py:273} INFO - 0 downstream tasks scheduled from follow-on schedule check
