[2024-02-10 10:23:20,111] {taskinstance.py:1159} INFO - Dependencies all met for <TaskInstance: test_dag_dependencies.write_date scheduled__2024-02-10T09:35:00+00:00 [queued]>
[2024-02-10 10:23:20,174] {taskinstance.py:1159} INFO - Dependencies all met for <TaskInstance: test_dag_dependencies.write_date scheduled__2024-02-10T09:35:00+00:00 [queued]>
[2024-02-10 10:23:20,176] {taskinstance.py:1356} INFO - 
--------------------------------------------------------------------------------
[2024-02-10 10:23:20,177] {taskinstance.py:1357} INFO - Starting attempt 2 of 2
[2024-02-10 10:23:20,180] {taskinstance.py:1358} INFO - 
--------------------------------------------------------------------------------
[2024-02-10 10:23:20,246] {taskinstance.py:1377} INFO - Executing <Task(BashOperator): write_date> on 2024-02-10 09:35:00+00:00
[2024-02-10 10:23:20,279] {standard_task_runner.py:52} INFO - Started process 35529 to run task
[2024-02-10 10:23:20,295] {standard_task_runner.py:79} INFO - Running: ['***', 'tasks', 'run', 'test_dag_dependencies', 'write_date', 'scheduled__2024-02-10T09:35:00+00:00', '--job-id', '118', '--raw', '--subdir', 'DAGS_FOLDER/dag_test_dependencies.py', '--cfg-path', '/tmp/tmpa546surs', '--error-file', '/tmp/tmpgetwhnd4']
[2024-02-10 10:23:20,296] {standard_task_runner.py:80} INFO - Job 118: Subtask write_date
[2024-02-10 10:23:21,058] {task_command.py:369} INFO - Running <TaskInstance: test_dag_dependencies.write_date scheduled__2024-02-10T09:35:00+00:00 [running]> on host f4c5b03650dc
[2024-02-10 10:23:21,472] {taskinstance.py:1571} INFO - Exporting the following env vars:
AIRFLOW_CTX_DAG_EMAIL=fidiasierides@gmail.com
AIRFLOW_CTX_DAG_OWNER=Fidias
AIRFLOW_CTX_DAG_ID=test_dag_dependencies
AIRFLOW_CTX_TASK_ID=write_date
AIRFLOW_CTX_EXECUTION_DATE=2024-02-10T09:35:00+00:00
AIRFLOW_CTX_TRY_NUMBER=2
AIRFLOW_CTX_DAG_RUN_ID=scheduled__2024-02-10T09:35:00+00:00
[2024-02-10 10:23:21,494] {subprocess.py:62} INFO - Tmp dir root location: 
 /tmp
[2024-02-10 10:23:21,519] {subprocess.py:74} INFO - Running command: ['bash', '-c', 'cd "~/Documents/GitHub/weather-data-store" && date >> date.txt']
[2024-02-10 10:23:21,697] {subprocess.py:85} INFO - Output:
[2024-02-10 10:23:21,724] {subprocess.py:92} INFO - bash: line 1: cd: ~/Documents/GitHub/weather-data-store: No such file or directory
[2024-02-10 10:23:21,727] {subprocess.py:96} INFO - Command exited with return code 1
[2024-02-10 10:23:22,123] {taskinstance.py:1889} ERROR - Task failed with exception
Traceback (most recent call last):
  File "/home/airflow/.local/lib/python3.7/site-packages/airflow/operators/bash.py", line 195, in execute
    f'Bash command failed. The command returned a non-zero exit code {result.exit_code}.'
airflow.exceptions.AirflowException: Bash command failed. The command returned a non-zero exit code 1.
[2024-02-10 10:23:22,239] {taskinstance.py:1400} INFO - Marking task as FAILED. dag_id=test_dag_dependencies, task_id=write_date, execution_date=20240210T093500, start_date=20240210T102320, end_date=20240210T102322
[2024-02-10 10:23:22,431] {standard_task_runner.py:97} ERROR - Failed to execute job 118 for task write_date (Bash command failed. The command returned a non-zero exit code 1.; 35529)
[2024-02-10 10:23:22,510] {local_task_job.py:156} INFO - Task exited with return code 1
[2024-02-10 10:23:23,264] {local_task_job.py:273} INFO - 0 downstream tasks scheduled from follow-on schedule check
