[2024-02-10 23:39:16,196] {taskinstance.py:1159} INFO - Dependencies all met for <TaskInstance: test_dag.write_date_file scheduled__2024-02-10T23:17:00+00:00 [queued]>
[2024-02-10 23:39:16,288] {taskinstance.py:1159} INFO - Dependencies all met for <TaskInstance: test_dag.write_date_file scheduled__2024-02-10T23:17:00+00:00 [queued]>
[2024-02-10 23:39:16,302] {taskinstance.py:1356} INFO - 
--------------------------------------------------------------------------------
[2024-02-10 23:39:16,303] {taskinstance.py:1357} INFO - Starting attempt 2 of 2
[2024-02-10 23:39:16,311] {taskinstance.py:1358} INFO - 
--------------------------------------------------------------------------------
[2024-02-10 23:39:16,387] {taskinstance.py:1377} INFO - Executing <Task(BashOperator): write_date_file> on 2024-02-10 23:17:00+00:00
[2024-02-10 23:39:16,418] {standard_task_runner.py:52} INFO - Started process 2045 to run task
[2024-02-10 23:39:16,508] {standard_task_runner.py:79} INFO - Running: ['***', 'tasks', 'run', 'test_dag', 'write_date_file', 'scheduled__2024-02-10T23:17:00+00:00', '--job-id', '674', '--raw', '--subdir', 'DAGS_FOLDER/dag_test_simple.py', '--cfg-path', '/tmp/tmp33elxfau', '--error-file', '/tmp/tmpgpp5rzg4']
[2024-02-10 23:39:16,529] {standard_task_runner.py:80} INFO - Job 674: Subtask write_date_file
[2024-02-10 23:39:17,107] {task_command.py:369} INFO - Running <TaskInstance: test_dag.write_date_file scheduled__2024-02-10T23:17:00+00:00 [running]> on host f4c5b03650dc
[2024-02-10 23:39:17,677] {taskinstance.py:1571} INFO - Exporting the following env vars:
AIRFLOW_CTX_DAG_EMAIL=fidiasierides@gmail.com
AIRFLOW_CTX_DAG_OWNER=Fidias
AIRFLOW_CTX_DAG_ID=test_dag
AIRFLOW_CTX_TASK_ID=write_date_file
AIRFLOW_CTX_EXECUTION_DATE=2024-02-10T23:17:00+00:00
AIRFLOW_CTX_TRY_NUMBER=2
AIRFLOW_CTX_DAG_RUN_ID=scheduled__2024-02-10T23:17:00+00:00
[2024-02-10 23:39:17,683] {subprocess.py:62} INFO - Tmp dir root location: 
 /tmp
[2024-02-10 23:39:17,688] {subprocess.py:74} INFO - Running command: ['bash', '-c', 'cd ~/Users/fidiasieridis/Documents/GitHub/weather-data-store && date >> ai_core.txt']
[2024-02-10 23:39:17,738] {subprocess.py:85} INFO - Output:
[2024-02-10 23:39:17,745] {subprocess.py:92} INFO - bash: line 1: cd: /home/***/Users/fidiasieridis/Documents/GitHub/weather-data-store: No such file or directory
[2024-02-10 23:39:17,754] {subprocess.py:96} INFO - Command exited with return code 1
[2024-02-10 23:39:17,789] {taskinstance.py:1889} ERROR - Task failed with exception
Traceback (most recent call last):
  File "/home/airflow/.local/lib/python3.7/site-packages/airflow/operators/bash.py", line 195, in execute
    f'Bash command failed. The command returned a non-zero exit code {result.exit_code}.'
airflow.exceptions.AirflowException: Bash command failed. The command returned a non-zero exit code 1.
[2024-02-10 23:39:17,797] {taskinstance.py:1400} INFO - Marking task as FAILED. dag_id=test_dag, task_id=write_date_file, execution_date=20240210T231700, start_date=20240210T233916, end_date=20240210T233917
[2024-02-10 23:39:17,840] {standard_task_runner.py:97} ERROR - Failed to execute job 674 for task write_date_file (Bash command failed. The command returned a non-zero exit code 1.; 2045)
[2024-02-10 23:39:17,891] {local_task_job.py:156} INFO - Task exited with return code 1
[2024-02-10 23:39:17,980] {local_task_job.py:273} INFO - 0 downstream tasks scheduled from follow-on schedule check
