[2024-02-10 13:30:27,258] {taskinstance.py:1159} INFO - Dependencies all met for <TaskInstance: test_dag_dependencies.write_date scheduled__2024-02-10T13:23:00+00:00 [queued]>
[2024-02-10 13:30:27,268] {taskinstance.py:1159} INFO - Dependencies all met for <TaskInstance: test_dag_dependencies.write_date scheduled__2024-02-10T13:23:00+00:00 [queued]>
[2024-02-10 13:30:27,269] {taskinstance.py:1356} INFO - 
--------------------------------------------------------------------------------
[2024-02-10 13:30:27,270] {taskinstance.py:1357} INFO - Starting attempt 1 of 2
[2024-02-10 13:30:27,271] {taskinstance.py:1358} INFO - 
--------------------------------------------------------------------------------
[2024-02-10 13:30:27,285] {taskinstance.py:1377} INFO - Executing <Task(BashOperator): write_date> on 2024-02-10 13:23:00+00:00
[2024-02-10 13:30:27,291] {standard_task_runner.py:52} INFO - Started process 795 to run task
[2024-02-10 13:30:27,297] {standard_task_runner.py:79} INFO - Running: ['***', 'tasks', 'run', 'test_dag_dependencies', 'write_date', 'scheduled__2024-02-10T13:23:00+00:00', '--job-id', '281', '--raw', '--subdir', 'DAGS_FOLDER/dag_test_dependencies.py', '--cfg-path', '/tmp/tmpbj6_h5zi', '--error-file', '/tmp/tmp27zer9zm']
[2024-02-10 13:30:27,298] {standard_task_runner.py:80} INFO - Job 281: Subtask write_date
[2024-02-10 13:30:27,359] {task_command.py:369} INFO - Running <TaskInstance: test_dag_dependencies.write_date scheduled__2024-02-10T13:23:00+00:00 [running]> on host f4c5b03650dc
[2024-02-10 13:30:27,408] {taskinstance.py:1571} INFO - Exporting the following env vars:
AIRFLOW_CTX_DAG_EMAIL=fidiasierides@gmail.com
AIRFLOW_CTX_DAG_OWNER=Fidias
AIRFLOW_CTX_DAG_ID=test_dag_dependencies
AIRFLOW_CTX_TASK_ID=write_date
AIRFLOW_CTX_EXECUTION_DATE=2024-02-10T13:23:00+00:00
AIRFLOW_CTX_TRY_NUMBER=1
AIRFLOW_CTX_DAG_RUN_ID=scheduled__2024-02-10T13:23:00+00:00
[2024-02-10 13:30:27,412] {subprocess.py:62} INFO - Tmp dir root location: 
 /tmp
[2024-02-10 13:30:27,413] {subprocess.py:74} INFO - Running command: ['bash', '-c', 'pwd && cd .. && cd .. && pwd && cd ~/Users/fidiasieridis/Documents/GitHub/weather-data-store && date >> date.txt']
[2024-02-10 13:30:27,420] {subprocess.py:85} INFO - Output:
[2024-02-10 13:30:27,420] {subprocess.py:92} INFO - /tmp/***tmp95oknhnd
[2024-02-10 13:30:27,421] {subprocess.py:92} INFO - /
[2024-02-10 13:30:27,422] {subprocess.py:92} INFO - bash: line 1: cd: /home/***/Users/fidiasieridis/Documents/GitHub/weather-data-store: No such file or directory
[2024-02-10 13:30:27,423] {subprocess.py:96} INFO - Command exited with return code 1
[2024-02-10 13:30:27,437] {taskinstance.py:1889} ERROR - Task failed with exception
Traceback (most recent call last):
  File "/home/airflow/.local/lib/python3.7/site-packages/airflow/operators/bash.py", line 195, in execute
    f'Bash command failed. The command returned a non-zero exit code {result.exit_code}.'
airflow.exceptions.AirflowException: Bash command failed. The command returned a non-zero exit code 1.
[2024-02-10 13:30:27,441] {taskinstance.py:1400} INFO - Marking task as UP_FOR_RETRY. dag_id=test_dag_dependencies, task_id=write_date, execution_date=20240210T132300, start_date=20240210T133027, end_date=20240210T133027
[2024-02-10 13:30:27,453] {standard_task_runner.py:97} ERROR - Failed to execute job 281 for task write_date (Bash command failed. The command returned a non-zero exit code 1.; 795)
[2024-02-10 13:30:27,480] {local_task_job.py:156} INFO - Task exited with return code 1
[2024-02-10 13:30:27,517] {local_task_job.py:273} INFO - 0 downstream tasks scheduled from follow-on schedule check
