[2024-02-11 12:30:11,289] {taskinstance.py:1159} INFO - Dependencies all met for <TaskInstance: test_dag_dependencies.write_date scheduled__2024-02-11T12:24:00+00:00 [queued]>
[2024-02-11 12:30:11,297] {taskinstance.py:1159} INFO - Dependencies all met for <TaskInstance: test_dag_dependencies.write_date scheduled__2024-02-11T12:24:00+00:00 [queued]>
[2024-02-11 12:30:11,297] {taskinstance.py:1356} INFO - 
--------------------------------------------------------------------------------
[2024-02-11 12:30:11,297] {taskinstance.py:1357} INFO - Starting attempt 2 of 2
[2024-02-11 12:30:11,298] {taskinstance.py:1358} INFO - 
--------------------------------------------------------------------------------
[2024-02-11 12:30:11,306] {taskinstance.py:1377} INFO - Executing <Task(BashOperator): write_date> on 2024-02-11 12:24:00+00:00
[2024-02-11 12:30:11,309] {standard_task_runner.py:52} INFO - Started process 413 to run task
[2024-02-11 12:30:11,312] {standard_task_runner.py:79} INFO - Running: ['***', 'tasks', 'run', 'test_dag_dependencies', 'write_date', 'scheduled__2024-02-11T12:24:00+00:00', '--job-id', '819', '--raw', '--subdir', 'DAGS_FOLDER/dag_test_dependencies.py', '--cfg-path', '/tmp/tmpsrqwe5j3', '--error-file', '/tmp/tmpuouaxx77']
[2024-02-11 12:30:11,313] {standard_task_runner.py:80} INFO - Job 819: Subtask write_date
[2024-02-11 12:30:11,367] {task_command.py:369} INFO - Running <TaskInstance: test_dag_dependencies.write_date scheduled__2024-02-11T12:24:00+00:00 [running]> on host 354d8ce2bde7
[2024-02-11 12:30:11,418] {taskinstance.py:1571} INFO - Exporting the following env vars:
AIRFLOW_CTX_DAG_EMAIL=fidiasierides@gmail.com
AIRFLOW_CTX_DAG_OWNER=Fidias
AIRFLOW_CTX_DAG_ID=test_dag_dependencies
AIRFLOW_CTX_TASK_ID=write_date
AIRFLOW_CTX_EXECUTION_DATE=2024-02-11T12:24:00+00:00
AIRFLOW_CTX_TRY_NUMBER=2
AIRFLOW_CTX_DAG_RUN_ID=scheduled__2024-02-11T12:24:00+00:00
[2024-02-11 12:30:11,421] {subprocess.py:62} INFO - Tmp dir root location: 
 /tmp
[2024-02-11 12:30:11,422] {subprocess.py:74} INFO - Running command: ['bash', '-c', 'cd ~/Documents/AICore/pinterest-data-pipeline && date >> date.txt']
[2024-02-11 12:30:11,428] {subprocess.py:85} INFO - Output:
[2024-02-11 12:30:11,430] {subprocess.py:92} INFO - bash: line 1: cd: /home/***/Documents/AICore/pinterest-data-pipeline: No such file or directory
[2024-02-11 12:30:11,431] {subprocess.py:96} INFO - Command exited with return code 1
[2024-02-11 12:30:11,446] {taskinstance.py:1889} ERROR - Task failed with exception
Traceback (most recent call last):
  File "/home/airflow/.local/lib/python3.7/site-packages/airflow/operators/bash.py", line 195, in execute
    f'Bash command failed. The command returned a non-zero exit code {result.exit_code}.'
airflow.exceptions.AirflowException: Bash command failed. The command returned a non-zero exit code 1.
[2024-02-11 12:30:11,449] {taskinstance.py:1400} INFO - Marking task as FAILED. dag_id=test_dag_dependencies, task_id=write_date, execution_date=20240211T122400, start_date=20240211T123011, end_date=20240211T123011
[2024-02-11 12:30:11,455] {standard_task_runner.py:97} ERROR - Failed to execute job 819 for task write_date (Bash command failed. The command returned a non-zero exit code 1.; 413)
[2024-02-11 12:30:11,496] {local_task_job.py:156} INFO - Task exited with return code 1
[2024-02-11 12:30:11,518] {local_task_job.py:273} INFO - 0 downstream tasks scheduled from follow-on schedule check
